<?xml version="1.0" ?>
<robot name="simplebot">
    <!-- ******** WORLD LINK ******** -->
    <link name="world" />
    <!-- ******** BASE LINK ******** -->
    <link name="base">
        <visual>
            <geometry>
                <box size="0.1 0.1 0.25" />
            </geometry>
        </visual>
        <collision>
            <geometry>
                <box size="0.1 0.1 0.25" />
            </geometry>
        </collision>
        
<inertial>
            <mass value="0.1" />
            <inertia ixx="0.03" iyy="0.03" izz="0.03" ixy="0.0" ixz="0.0" iyz="0.0" />
        </inertial>

    </link>
    <!-- ******** MOVE LINK ******** -->
    <link name="child_link">
        <visual>
            <geometry>
                <box size="0.05 0.05 0.15" />
            </geometry>
        </visual>
        <collision>
            <geometry>
                <box size="0.05 0.05 0.15" />
            </geometry>
        </collision>
        
<inertial>
            <mass value="0.1" />
            <inertia ixx="0.03" iyy="0.03" izz="0.03" ixy="0.0" ixz="0.0" iyz="0.0" />
        </inertial>

    </link>
    <!-- ******** JOINTS ******** -->
    <joint name="worldFix" type="fixed">
        <parent link="world" />
        <child link="base" />
    </joint>
    <joint name="joint1" type="continuous">
        <parent link="base" />
        <child link="child_link" />
        <axis xyz="1 0 0" />
        <origin xyz="0 0 .2" rpy="0 0 0" />
    </joint>
    <!-- ******** GAZEBO ******** -->
    <!--end robot-->
    
<transmission name="trans_joint1">
        <type>transmission_interface/SimpleTransmission</type>
        <joint name="joint1">
            <hardwareInterface>hardware_interface/EffortJointInterface</hardwareInterface>
        </joint>
        <actuator name="joint1_motor">
            <hardwareInterface>hardware_interface/EffortJointInterface</hardwareInterface>
            <mechanicalReduction>1</mechanicalReduction>
        </actuator>
    </transmission>
    <gazebo>
        <plugin name="gazebo_ros_control" filename="libgazebo_ros_control.so">
            <legacyModeNS value="true"/>
            <robotNamespace>/</robotNamespace>
        </plugin>
    </gazebo>
</robot>