<?xml version='1.0'?>

<robot name="simplebot">
<!-- ******** WORLD LINK ******** -->
  <link name="world"/>
<!-- ******** BASE LINK ******** -->
  <link name="base">
    <visual>
      <geometry>
        <box size="0.1 0.1 0.25"/>
      </geometry>
    </visual>

    <collision>
      <geometry>
        <box size="0.1 0.1 0.25"/>
      </geometry>
    </collision>

  </link>

<!-- ******** MOVE LINK ******** -->
  <link name="child_link">
    <visual>
      <geometry>
        <box size="0.05 0.05 0.15"/>
      </geometry>
    </visual>

    <collision>
      <geometry>
        <box size="0.05 0.05 0.15"/>
      </geometry>
    </collision>
  </link>

<!-- ******** JOINTS ******** -->
  <joint name="worldFix" type="fixed">
    <parent link="world"/>
    <child link="base"/>
  </joint>  

  <joint name="joint1" type="continuous">
    <parent link="base"/>
    <child link="child_link"/>
    <axis xyz="1 0 0"/>
    <origin xyz="0 0 .2" rpy="0 0 0"/>
  </joint>

<!-- ******** GAZEBO ******** -->

<!--end robot-->
</robot>